2024-12-11 18:25:30,616 ERROR: Error in handle_connect: (psycopg2.OperationalError) SSL connection has been closed unexpectedly

[SQL: SELECT "user".id AS user_id, "user".username AS user_username, "user".email AS user_email, "user".password_hash AS user_password_hash, "user".is_verified AS user_is_verified, "user".is_moderator AS user_is_moderator, "user".avatar AS user_avatar, "user".display_name AS user_display_name, "user".status AS user_status, "user".presence_state AS user_presence_state, "user".accent_color AS user_accent_color, "user".bio AS user_bio, "user".location AS user_location, "user".banner_color AS user_banner_color, "user".custom_status AS user_custom_status, "user".status_emoji AS user_status_emoji, "user".last_seen AS user_last_seen, "user".created_at AS user_created_at 
FROM "user" 
WHERE "user".id = %(pk_1)s]
[parameters: {'pk_1': 2}]
(Background on this error at: https://sqlalche.me/e/20/e3q8) [in /home/runner/TornadoChatRoom/app.py:372]
Traceback (most recent call last):
  File "/home/runner/TornadoChatRoom/.pythonlibs/lib/python3.11/site-packages/sqlalchemy/engine/base.py", line 1967, in _exec_single_context
    self.dialect.do_execute(
  File "/home/runner/TornadoChatRoom/.pythonlibs/lib/python3.11/site-packages/sqlalchemy/engine/default.py", line 941, in do_execute
    cursor.execute(statement, parameters)
psycopg2.OperationalError: SSL connection has been closed unexpectedly


The above exception was the direct cause of the following exception:

Traceback (most recent call last):
  File "/home/runner/TornadoChatRoom/app.py", line 353, in handle_connect
    if current_user.is_authenticated:
       ^^^^^^^^^^^^^^^^^^^^^^^^^^^^^
  File "/home/runner/TornadoChatRoom/.pythonlibs/lib/python3.11/site-packages/werkzeug/local.py", line 318, in __get__
    obj = instance._get_current_object()
          ^^^^^^^^^^^^^^^^^^^^^^^^^^^^^^
  File "/home/runner/TornadoChatRoom/.pythonlibs/lib/python3.11/site-packages/werkzeug/local.py", line 526, in _get_current_object
    return get_name(local())
                    ^^^^^^^
  File "/home/runner/TornadoChatRoom/.pythonlibs/lib/python3.11/site-packages/flask_login/utils.py", line 25, in <lambda>
    current_user = LocalProxy(lambda: _get_user())
                                      ^^^^^^^^^^^
  File "/home/runner/TornadoChatRoom/.pythonlibs/lib/python3.11/site-packages/flask_login/utils.py", line 370, in _get_user
    current_app.login_manager._load_user()
  File "/home/runner/TornadoChatRoom/.pythonlibs/lib/python3.11/site-packages/flask_login/login_manager.py", line 364, in _load_user
    user = self._user_callback(user_id)
           ^^^^^^^^^^^^^^^^^^^^^^^^^^^^
  File "/home/runner/TornadoChatRoom/app.py", line 193, in load_user
    return User.query.get(int(id))
           ^^^^^^^^^^^^^^^^^^^^^^^
  File "<string>", line 2, in get
  File "/home/runner/TornadoChatRoom/.pythonlibs/lib/python3.11/site-packages/sqlalchemy/util/deprecations.py", line 386, in warned
    return fn(*args, **kwargs)  # type: ignore[no-any-return]
           ^^^^^^^^^^^^^^^^^^^
  File "/home/runner/TornadoChatRoom/.pythonlibs/lib/python3.11/site-packages/sqlalchemy/orm/query.py", line 1127, in get
    return self._get_impl(ident, loading.load_on_pk_identity)
           ^^^^^^^^^^^^^^^^^^^^^^^^^^^^^^^^^^^^^^^^^^^^^^^^^^
  File "/home/runner/TornadoChatRoom/.pythonlibs/lib/python3.11/site-packages/sqlalchemy/orm/query.py", line 1136, in _get_impl
    return self.session._get_impl(
           ^^^^^^^^^^^^^^^^^^^^^^^
  File "/home/runner/TornadoChatRoom/.pythonlibs/lib/python3.11/site-packages/sqlalchemy/orm/session.py", line 3873, in _get_impl
    return db_load_fn(
           ^^^^^^^^^^^
  File "/home/runner/TornadoChatRoom/.pythonlibs/lib/python3.11/site-packages/sqlalchemy/orm/loading.py", line 694, in load_on_pk_identity
    session.execute(
  File "/home/runner/TornadoChatRoom/.pythonlibs/lib/python3.11/site-packages/sqlalchemy/orm/session.py", line 2362, in execute
    return self._execute_internal(
           ^^^^^^^^^^^^^^^^^^^^^^^
  File "/home/runner/TornadoChatRoom/.pythonlibs/lib/python3.11/site-packages/sqlalchemy/orm/session.py", line 2247, in _execute_internal
    result: Result[Any] = compile_state_cls.orm_execute_statement(
                          ^^^^^^^^^^^^^^^^^^^^^^^^^^^^^^^^^^^^^^^^
  File "/home/runner/TornadoChatRoom/.pythonlibs/lib/python3.11/site-packages/sqlalchemy/orm/context.py", line 305, in orm_execute_statement
    result = conn.execute(
             ^^^^^^^^^^^^^
  File "/home/runner/TornadoChatRoom/.pythonlibs/lib/python3.11/site-packages/sqlalchemy/engine/base.py", line 1418, in execute
    return meth(
           ^^^^^
  File "/home/runner/TornadoChatRoom/.pythonlibs/lib/python3.11/site-packages/sqlalchemy/sql/elements.py", line 515, in _execute_on_connection
    return connection._execute_clauseelement(
           ^^^^^^^^^^^^^^^^^^^^^^^^^^^^^^^^^^
  File "/home/runner/TornadoChatRoom/.pythonlibs/lib/python3.11/site-packages/sqlalchemy/engine/base.py", line 1640, in _execute_clauseelement
    ret = self._execute_context(
          ^^^^^^^^^^^^^^^^^^^^^^
  File "/home/runner/TornadoChatRoom/.pythonlibs/lib/python3.11/site-packages/sqlalchemy/engine/base.py", line 1846, in _execute_context
    return self._exec_single_context(
           ^^^^^^^^^^^^^^^^^^^^^^^^^^
  File "/home/runner/TornadoChatRoom/.pythonlibs/lib/python3.11/site-packages/sqlalchemy/engine/base.py", line 1986, in _exec_single_context
    self._handle_dbapi_exception(
  File "/home/runner/TornadoChatRoom/.pythonlibs/lib/python3.11/site-packages/sqlalchemy/engine/base.py", line 2355, in _handle_dbapi_exception
    raise sqlalchemy_exception.with_traceback(exc_info[2]) from e
  File "/home/runner/TornadoChatRoom/.pythonlibs/lib/python3.11/site-packages/sqlalchemy/engine/base.py", line 1967, in _exec_single_context
    self.dialect.do_execute(
  File "/home/runner/TornadoChatRoom/.pythonlibs/lib/python3.11/site-packages/sqlalchemy/engine/default.py", line 941, in do_execute
    cursor.execute(statement, parameters)
sqlalchemy.exc.OperationalError: (psycopg2.OperationalError) SSL connection has been closed unexpectedly

[SQL: SELECT "user".id AS user_id, "user".username AS user_username, "user".email AS user_email, "user".password_hash AS user_password_hash, "user".is_verified AS user_is_verified, "user".is_moderator AS user_is_moderator, "user".avatar AS user_avatar, "user".display_name AS user_display_name, "user".status AS user_status, "user".presence_state AS user_presence_state, "user".accent_color AS user_accent_color, "user".bio AS user_bio, "user".location AS user_location, "user".banner_color AS user_banner_color, "user".custom_status AS user_custom_status, "user".status_emoji AS user_status_emoji, "user".last_seen AS user_last_seen, "user".created_at AS user_created_at 
FROM "user" 
WHERE "user".id = %(pk_1)s]
[parameters: {'pk_1': 2}]
(Background on this error at: https://sqlalche.me/e/20/e3q8)
2024-12-11 18:25:31,280 INFO: User disconnecting: Hollow [in /home/runner/TornadoChatRoom/app.py:379]
2024-12-11 18:25:31,280 INFO: User disconnected: Hollow [in /home/runner/TornadoChatRoom/app.py:382]
2024-12-11 18:25:31,970 INFO: Client connecting with auth: None [in /home/runner/TornadoChatRoom/app.py:352]
2024-12-11 18:25:32,166 INFO: Authenticated user connecting: Hollow [in /home/runner/TornadoChatRoom/app.py:354]
2024-12-11 18:25:32,308 INFO: Sending user list with 2 users [in /home/runner/TornadoChatRoom/app.py:360]
2024-12-11 18:25:32,384 INFO: Sending categories list with 1 categories [in /home/runner/TornadoChatRoom/app.py:365]
2024-12-11 18:25:32,453 INFO: Client connected successfully: Hollow [in /home/runner/TornadoChatRoom/app.py:368]
2024-12-11 18:25:33,267 INFO: Client connecting with auth: None [in /home/runner/TornadoChatRoom/app.py:352]
2024-12-11 18:25:33,462 INFO: Authenticated user connecting: Hollow [in /home/runner/TornadoChatRoom/app.py:354]
2024-12-11 18:25:33,593 INFO: Sending user list with 2 users [in /home/runner/TornadoChatRoom/app.py:360]
2024-12-11 18:25:33,658 INFO: Sending categories list with 1 categories [in /home/runner/TornadoChatRoom/app.py:365]
2024-12-11 18:25:33,723 INFO: Client connected successfully: Hollow [in /home/runner/TornadoChatRoom/app.py:368]
2024-12-11 18:25:34,358 INFO: Client connecting with auth: None [in /home/runner/TornadoChatRoom/app.py:352]
2024-12-11 18:25:34,554 INFO: Authenticated user connecting: Hollow [in /home/runner/TornadoChatRoom/app.py:354]
2024-12-11 18:25:34,685 INFO: Sending user list with 2 users [in /home/runner/TornadoChatRoom/app.py:360]
2024-12-11 18:25:34,750 INFO: Sending categories list with 1 categories [in /home/runner/TornadoChatRoom/app.py:365]
2024-12-11 18:25:34,815 INFO: Client connected successfully: Hollow [in /home/runner/TornadoChatRoom/app.py:368]
2024-12-11 18:25:35,943 INFO: Client connecting with auth: None [in /home/runner/TornadoChatRoom/app.py:352]
2024-12-11 18:25:36,137 INFO: Authenticated user connecting: Hollow [in /home/runner/TornadoChatRoom/app.py:354]
2024-12-11 18:25:36,269 INFO: Sending user list with 2 users [in /home/runner/TornadoChatRoom/app.py:360]
2024-12-11 18:25:36,333 INFO: Sending categories list with 1 categories [in /home/runner/TornadoChatRoom/app.py:365]
2024-12-11 18:25:36,399 INFO: Client connected successfully: Hollow [in /home/runner/TornadoChatRoom/app.py:368]
2024-12-11 18:25:36,994 INFO: Client connecting with auth: None [in /home/runner/TornadoChatRoom/app.py:352]
2024-12-11 18:25:37,189 INFO: Authenticated user connecting: Hollow [in /home/runner/TornadoChatRoom/app.py:354]
2024-12-11 18:25:37,321 INFO: Sending user list with 2 users [in /home/runner/TornadoChatRoom/app.py:360]
2024-12-11 18:25:37,387 INFO: Sending categories list with 1 categories [in /home/runner/TornadoChatRoom/app.py:365]
2024-12-11 18:25:37,453 INFO: Client connected successfully: Hollow [in /home/runner/TornadoChatRoom/app.py:368]
2024-12-11 18:25:38,551 INFO: Client connecting with auth: None [in /home/runner/TornadoChatRoom/app.py:352]
2024-12-11 18:25:38,747 INFO: Authenticated user connecting: Hollow [in /home/runner/TornadoChatRoom/app.py:354]
