2024-12-11 19:41:02,155 INFO: Database initialized successfully [in /home/runner/TornadoChatRoom/app.py:578]
2024-12-11 19:41:02,221 INFO: Starting SocketIO server... [in /home/runner/TornadoChatRoom/app.py:585]
2024-12-11 19:41:03,419 INFO: Application startup [in /home/runner/TornadoChatRoom/app.py:80]
2024-12-11 19:41:05,043 INFO: Database initialized successfully [in /home/runner/TornadoChatRoom/app.py:578]
2024-12-11 19:41:05,107 INFO: Starting SocketIO server... [in /home/runner/TornadoChatRoom/app.py:585]
2024-12-11 19:41:05,637 INFO: Authenticated user connecting: Hollow [in /home/runner/TornadoChatRoom/app.py:425]
2024-12-11 19:41:05,984 ERROR: Error in handle_connect: 'User' object has no attribute 'presence_state' [in /home/runner/TornadoChatRoom/app.py:455]
Traceback (most recent call last):
  File "/home/runner/TornadoChatRoom/.pythonlibs/lib/python3.11/site-packages/flask_socketio/__init__.py", line 834, in _handle_event
    ret = handler(auth)
          ^^^^^^^^^^^^^
TypeError: handle_connect() takes 0 positional arguments but 1 was given

During handling of the above exception, another exception occurred:

Traceback (most recent call last):
  File "/home/runner/TornadoChatRoom/app.py", line 430, in handle_connect
    logger.info(f"Current presence state for {current_user.username}: {current_user.presence_state}")
                                                                       ^^^^^^^^^^^^^^^^^^^^^^^^^^^
AttributeError: 'User' object has no attribute 'presence_state'
2024-12-11 19:41:08,026 INFO: Authenticated user connecting: Hollow [in /home/runner/TornadoChatRoom/app.py:425]
2024-12-11 19:41:08,347 ERROR: Error in handle_connect: 'User' object has no attribute 'presence_state' [in /home/runner/TornadoChatRoom/app.py:455]
Traceback (most recent call last):
  File "/home/runner/TornadoChatRoom/.pythonlibs/lib/python3.11/site-packages/flask_socketio/__init__.py", line 834, in _handle_event
    ret = handler(auth)
          ^^^^^^^^^^^^^
TypeError: handle_connect() takes 0 positional arguments but 1 was given

During handling of the above exception, another exception occurred:

Traceback (most recent call last):
  File "/home/runner/TornadoChatRoom/app.py", line 430, in handle_connect
    logger.info(f"Current presence state for {current_user.username}: {current_user.presence_state}")
                                                                       ^^^^^^^^^^^^^^^^^^^^^^^^^^^
AttributeError: 'User' object has no attribute 'presence_state'
