2024-12-11 19:44:20,543 ERROR: Error in handle_connect: 'User' object has no attribute 'presence_state' [in /home/runner/TornadoChatRoom/app.py:455]
Traceback (most recent call last):
  File "/home/runner/TornadoChatRoom/.pythonlibs/lib/python3.11/site-packages/flask_socketio/__init__.py", line 834, in _handle_event
    ret = handler(auth)
          ^^^^^^^^^^^^^
TypeError: handle_connect() takes 0 positional arguments but 1 was given

During handling of the above exception, another exception occurred:

Traceback (most recent call last):
  File "/home/runner/TornadoChatRoom/app.py", line 430, in handle_connect
    logger.info(f"Current presence state for {current_user.username}: {current_user.presence_state}")
                                                                       ^^^^^^^^^^^^^^^^^^^^^^^^^^^
AttributeError: 'User' object has no attribute 'presence_state'
2024-12-11 19:44:21,143 INFO: Authenticated user connecting: Hollow [in /home/runner/TornadoChatRoom/app.py:425]
2024-12-11 19:44:21,460 ERROR: Error in handle_connect: 'User' object has no attribute 'presence_state' [in /home/runner/TornadoChatRoom/app.py:455]
Traceback (most recent call last):
  File "/home/runner/TornadoChatRoom/.pythonlibs/lib/python3.11/site-packages/flask_socketio/__init__.py", line 834, in _handle_event
    ret = handler(auth)
          ^^^^^^^^^^^^^
TypeError: handle_connect() takes 0 positional arguments but 1 was given

During handling of the above exception, another exception occurred:

Traceback (most recent call last):
  File "/home/runner/TornadoChatRoom/app.py", line 430, in handle_connect
    logger.info(f"Current presence state for {current_user.username}: {current_user.presence_state}")
                                                                       ^^^^^^^^^^^^^^^^^^^^^^^^^^^
AttributeError: 'User' object has no attribute 'presence_state'
2024-12-11 19:44:21,912 INFO: Authenticated user connecting: Hollow [in /home/runner/TornadoChatRoom/app.py:425]
2024-12-11 19:44:22,235 ERROR: Error in handle_connect: 'User' object has no attribute 'presence_state' [in /home/runner/TornadoChatRoom/app.py:455]
Traceback (most recent call last):
  File "/home/runner/TornadoChatRoom/.pythonlibs/lib/python3.11/site-packages/flask_socketio/__init__.py", line 834, in _handle_event
    ret = handler(auth)
          ^^^^^^^^^^^^^
TypeError: handle_connect() takes 0 positional arguments but 1 was given

During handling of the above exception, another exception occurred:

Traceback (most recent call last):
  File "/home/runner/TornadoChatRoom/app.py", line 430, in handle_connect
    logger.info(f"Current presence state for {current_user.username}: {current_user.presence_state}")
                                                                       ^^^^^^^^^^^^^^^^^^^^^^^^^^^
AttributeError: 'User' object has no attribute 'presence_state'
2024-12-11 19:44:23,623 INFO: Authenticated user connecting: Hollow [in /home/runner/TornadoChatRoom/app.py:425]
2024-12-11 19:44:23,940 ERROR: Error in handle_connect: 'User' object has no attribute 'presence_state' [in /home/runner/TornadoChatRoom/app.py:455]
Traceback (most recent call last):
  File "/home/runner/TornadoChatRoom/.pythonlibs/lib/python3.11/site-packages/flask_socketio/__init__.py", line 834, in _handle_event
    ret = handler(auth)
          ^^^^^^^^^^^^^
TypeError: handle_connect() takes 0 positional arguments but 1 was given

During handling of the above exception, another exception occurred:

Traceback (most recent call last):
  File "/home/runner/TornadoChatRoom/app.py", line 430, in handle_connect
    logger.info(f"Current presence state for {current_user.username}: {current_user.presence_state}")
                                                                       ^^^^^^^^^^^^^^^^^^^^^^^^^^^
AttributeError: 'User' object has no attribute 'presence_state'
2024-12-11 19:44:24,707 INFO: Authenticated user connecting: Hollow [in /home/runner/TornadoChatRoom/app.py:425]
2024-12-11 19:44:25,023 ERROR: Error in handle_connect: 'User' object has no attribute 'presence_state' [in /home/runner/TornadoChatRoom/app.py:455]
Traceback (most recent call last):
  File "/home/runner/TornadoChatRoom/.pythonlibs/lib/python3.11/site-packages/flask_socketio/__init__.py", line 834, in _handle_event
    ret = handler(auth)
          ^^^^^^^^^^^^^
TypeError: handle_connect() takes 0 positional arguments but 1 was given

During handling of the above exception, another exception occurred:

Traceback (most recent call last):
  File "/home/runner/TornadoChatRoom/app.py", line 430, in handle_connect
    logger.info(f"Current presence state for {current_user.username}: {current_user.presence_state}")
                                                                       ^^^^^^^^^^^^^^^^^^^^^^^^^^^
AttributeError: 'User' object has no attribute 'presence_state'
2024-12-11 19:44:25,787 INFO: Authenticated user connecting: Hollow [in /home/runner/TornadoChatRoom/app.py:425]
2024-12-11 19:44:26,104 ERROR: Error in handle_connect: 'User' object has no attribute 'presence_state' [in /home/runner/TornadoChatRoom/app.py:455]
Traceback (most recent call last):
  File "/home/runner/TornadoChatRoom/.pythonlibs/lib/python3.11/site-packages/flask_socketio/__init__.py", line 834, in _handle_event
    ret = handler(auth)
          ^^^^^^^^^^^^^
TypeError: handle_connect() takes 0 positional arguments but 1 was given

During handling of the above exception, another exception occurred:

Traceback (most recent call last):
  File "/home/runner/TornadoChatRoom/app.py", line 430, in handle_connect
    logger.info(f"Current presence state for {current_user.username}: {current_user.presence_state}")
                                                                       ^^^^^^^^^^^^^^^^^^^^^^^^^^^
AttributeError: 'User' object has no attribute 'presence_state'
2024-12-11 19:44:27,404 INFO: Authenticated user connecting: Hollow [in /home/runner/TornadoChatRoom/app.py:425]
2024-12-11 19:44:27,723 ERROR: Error in handle_connect: 'User' object has no attribute 'presence_state' [in /home/runner/TornadoChatRoom/app.py:455]
Traceback (most recent call last):
  File "/home/runner/TornadoChatRoom/.pythonlibs/lib/python3.11/site-packages/flask_socketio/__init__.py", line 834, in _handle_event
    ret = handler(auth)
          ^^^^^^^^^^^^^
TypeError: handle_connect() takes 0 positional arguments but 1 was given

During handling of the above exception, another exception occurred:

Traceback (most recent call last):
  File "/home/runner/TornadoChatRoom/app.py", line 430, in handle_connect
    logger.info(f"Current presence state for {current_user.username}: {current_user.presence_state}")
                                                                       ^^^^^^^^^^^^^^^^^^^^^^^^^^^
AttributeError: 'User' object has no attribute 'presence_state'
2024-12-11 19:44:29,403 INFO: Authenticated user connecting: Hollow [in /home/runner/TornadoChatRoom/app.py:425]
2024-12-11 19:44:29,720 ERROR: Error in handle_connect: 'User' object has no attribute 'presence_state' [in /home/runner/TornadoChatRoom/app.py:455]
Traceback (most recent call last):
  File "/home/runner/TornadoChatRoom/.pythonlibs/lib/python3.11/site-packages/flask_socketio/__init__.py", line 834, in _handle_event
    ret = handler(auth)
          ^^^^^^^^^^^^^
TypeError: handle_connect() takes 0 positional arguments but 1 was given

During handling of the above exception, another exception occurred:

Traceback (most recent call last):
  File "/home/runner/TornadoChatRoom/app.py", line 430, in handle_connect
    logger.info(f"Current presence state for {current_user.username}: {current_user.presence_state}")
                                                                       ^^^^^^^^^^^^^^^^^^^^^^^^^^^
AttributeError: 'User' object has no attribute 'presence_state'
2024-12-11 19:44:31,419 INFO: Authenticated user connecting: Hollow [in /home/runner/TornadoChatRoom/app.py:425]
2024-12-11 19:44:31,735 ERROR: Error in handle_connect: 'User' object has no attribute 'presence_state' [in /home/runner/TornadoChatRoom/app.py:455]
Traceback (most recent call last):
  File "/home/runner/TornadoChatRoom/.pythonlibs/lib/python3.11/site-packages/flask_socketio/__init__.py", line 834, in _handle_event
    ret = handler(auth)
          ^^^^^^^^^^^^^
TypeError: handle_connect() takes 0 positional arguments but 1 was given

During handling of the above exception, another exception occurred:

Traceback (most recent call last):
  File "/home/runner/TornadoChatRoom/app.py", line 430, in handle_connect
    logger.info(f"Current presence state for {current_user.username}: {current_user.presence_state}")
                                                                       ^^^^^^^^^^^^^^^^^^^^^^^^^^^
AttributeError: 'User' object has no attribute 'presence_state'
2024-12-11 19:44:32,426 INFO: Authenticated user connecting: Hollow [in /home/runner/TornadoChatRoom/app.py:425]
2024-12-11 19:44:32,742 ERROR: Error in handle_connect: 'User' object has no attribute 'presence_state' [in /home/runner/TornadoChatRoom/app.py:455]
Traceback (most recent call last):
  File "/home/runner/TornadoChatRoom/.pythonlibs/lib/python3.11/site-packages/flask_socketio/__init__.py", line 834, in _handle_event
    ret = handler(auth)
          ^^^^^^^^^^^^^
TypeError: handle_connect() takes 0 positional arguments but 1 was given

During handling of the above exception, another exception occurred:

Traceback (most recent call last):
  File "/home/runner/TornadoChatRoom/app.py", line 430, in handle_connect
    logger.info(f"Current presence state for {current_user.username}: {current_user.presence_state}")
                                                                       ^^^^^^^^^^^^^^^^^^^^^^^^^^^
AttributeError: 'User' object has no attribute 'presence_state'
